Workbook
Name Slicer_Grade: #N/A
Name Slicer_Sub_Skill_Measure: #N/A

Sheet Trend Analysis
A1: Grade | B1: (All)
A2: Sub_Skill_Measure | B2: Word Reading (WRF)
A4: Row Labels | B4: Average of BOY_Proficient | C4: Average of MOY_Proficient | D4: Average of EOY_Proficient
A5: 2022 | B5: 0.305 | C5: 0.555 | D5: 0.6025
A6: 2023 | B6: 0.4225 | C6: 0.5625 | D6: 0.6525
A7: 2024 | B7: 0.5575 | C7: 0.6875 | D7: 0.7075
A8: 2025 | B8: 0.5425 | C8: 0.7075 | D8: 0.71
A9: 2026 | B9: 0.466 | C9: 0.606 | D9: 0.604
A10: Grand Total | B10: 0.45904762 | C10: 0.62285714 | D10: 0.65285714

Sheet Cohort Analysis
A3: Sub_Skill_Measure | B3: Letter Sounds (NWF-CLS)
A5: Average of EOY_Proficient | B5: Column Labels
A6: Row Labels | B6: K | C6: 1 | D6: 2 | E6: 3 | F6: 4 | G6: Grand Total
A7: 2022 | B7: 0.76 | C7: 0.64 | D7: 0.65 | E7: 0.49 | G7: 0.635
A8: 2023 | B8: 0.84 | C8: 0.8 | D8: 0.79 | E8: 0.57 | G8: 0.75
A9: 2024 | B9: 0.87 | C9: 0.79 | D9: 0.82 | E9: 0.7 | G9: 0.795
A10: 2025 | B10: 0.98 | C10: 0.69 | D10: 0.76 | E10: 0.64 | G10: 0.7675
A11: 2026 | B11: 0.97 | C11: 0.89 | D11: 0.77 | E11: 0.64 | F11: 0.25 | G11: 0.704
A12: Grand Total | B12: 0.884 | C12: 0.762 | D12: 0.758 | E12: 0.608 | F12: 0.25 | G12: 0.72904762

Sheet Tier Movement
A1: Grade | B1: 1 | F1: Grade | G1: 1
A2: Sub_Skill_Measure | B2: Composite Score | F2: Sub_Skill_Measure | G2: Word Reading (WRF)
A3: Data_Year | B3: 2024 | F3: Data_Year | G3: 2026
A5: Average of BOY_Red | B5: Average of MOY_Red | C5: Average of EOY_Red | F5: Average of BOY_Blue | G5: Average of MOY_Blue | H5: Average of EOY_Blue
A6: 0.17 | B6: 0.15 | C6: 0.08 | F6: 0.3 | G6: 0.42 | H6: 0.43

Sheet Sheet6
A1: Select Cohort: | B1: 22K
A2: Select Measure: | B2: Letter Sounds (NWF-CLS)
A4: Grade | B4: Year | C4: EOY_Proficient
A5: K | B5: =IF($B$1="22K", 2022, IF($B$1="23K", 2023, IF($B$1="24K", 2024, IF($B$1="25K", 2025, IF($B$1="26K", 2026, ""))))) -> 2022 | C5: =AVERAGEIFS(Historical_Master_Data!S:S, Historical_Master_Data!B:B, A5, Historical_Master_Data!A:A, B5, Historical_Master_Data!C:C, $B$2) -> 0.76
A6: 1 | B6: =B5+1 -> 2023 | C6: =AVERAGEIFS(Historical_Master_Data!S:S, Historical_Master_Data!B:B, A6, Historical_Master_Data!A:A, B6, Historical_Master_Data!C:C, $B$2) -> 0.8
A7: 2 | B7: =B6+1 -> 2024 | C7: =AVERAGEIFS(Historical_Master_Data!S:S, Historical_Master_Data!B:B, A7, Historical_Master_Data!A:A, B7, Historical_Master_Data!C:C, $B$2) -> 0.82
A8: 3 | B8: =B7+1 -> 2025 | C8: =AVERAGEIFS(Historical_Master_Data!S:S, Historical_Master_Data!B:B, A8, Historical_Master_Data!A:A, B8, Historical_Master_Data!C:C, $B$2) -> 0.64
A9: 4 | B9: =B8+1 -> 2026 | C9: =AVERAGEIFS(Historical_Master_Data!S:S, Historical_Master_Data!B:B, A9, Historical_Master_Data!A:A, B9, Historical_Master_Data!C:C, $B$2) -> 0.25
A10: 5 | B10: =B9+1 -> 2027 | C10: =AVERAGEIFS(Historical_Master_Data!S:S, Historical_Master_Data!B:B, A10, Historical_Master_Data!A:A, B10, Historical_Master_Data!C:C, $B$2) -> #DIV/0!

Sheet Historical_Master_Data
A1: Data_Year | B1: Grade | C1: Sub_Skill_Measure | D1: Total_Students_N | E1: BOY_Red | F1: BOY_Yellow | G1: BOY_Green | H1: BOY_Blue | I1: MOY_Red | J1: MOY_Yellow | K1: MOY_Green | L1: MOY_Blue | M1: EOY_Red | N1: EOY_Yellow | O1: EOY_Green | P1: EOY_Blue | Q1: BOY_Proficient | R1: MOY_Proficient | S1: EOY_Proficient | T1: In_Year_Growth
A2: 2022 | B2: 1 | C2: Composite Score | D2: 98 | E2: 0.31 | F2: 0.22 | G2: 0.32 | H2: 0.15 | I2: 0.37 | J2: 0.14 | K2: 0.32 | L2: 0.17 | M2: 0.13 | N2: 0.17 | O2: 0.4 | P2: 0.3 | Q2: =SUM(G2:H2) -> 0.47 | R2: =SUM(K2:L2) -> 0.49 | S2: =SUM(O2:P2) -> 0.7 | T2: =S2-Q2 -> 0.23
A3: 2023 | B3: 1 | C3: Composite Score | D3: 100 | E3: 0.29 | F3: 0.26 | G3: 0.26 | H3: 0.19 | I3: 0.21 | J3: 0.24 | K3: 0.33 | L3: 0.22 | M3: 0.11 | N3: 0.12 | O3: 0.36 | P3: 0.41 | Q3: =SUM(G3:H3) -> 0.45 | R3: =SUM(K3:L3) -> 0.55 | S3: =SUM(O3:P3) -> 0.77 | T3: =S3-Q3 -> 0.32
A4: 2024 | B4: 1 | C4: Composite Score | D4: 106 | E4: 0.17 | F4: 0.14 | G4: 0.4 | H4: 0.29 | I4: 0.15 | J4: 0.13 | K4: 0.4 | L4: 0.32 | M4: 0.08 | N4: 0.14 | O4: 0.29 | P4: 0.49 | Q4: =SUM(G4:H4) -> 0.69 | R4: =SUM(K4:L4) -> 0.72 | S4: =SUM(O4:P4) -> 0.78 | T4: =S4-Q4 -> 0.09
A5: 2025 | B5: 1 | C5: Composite Score | D5: 95 | E5: 0.18 | F5: 0.26 | G5: 0.26 | H5: 0.3 | I5: 0.19 | J5: 0.18 | K5: 0.27 | L5: 0.36 | M5: 0.12 | N5: 0.18 | O5: 0.31 | P5: 0.39 | Q5: =SUM(G5:H5) -> 0.56 | R5: =SUM(K5:L5) -> 0.63 | S5: =SUM(O5:P5) -> 0.7 | T5: =S5-Q5 -> 0.14
A6: 2026 | B6: 1 | C6: Composite Score | D6: 88 | E6: 0.09 | F6: 0.2 | G6: 0.38 | H6: 0.33 | I6: 0.13 | J6: 0.15 | K6: 0.33 | L6: 0.39 | M6: 0.09 | N6: 0.05 | O6: 0.39 | P6: 0.47 | Q6: =SUM(G6:H6) -> 0.71 | R6: =SUM(K6:L6) -> 0.72 | S6: =SUM(O6:P6) -> 0.86 | T6: =S6-Q6 -> 0.15
A7: 2022 | B7: 1 | C7: Decoding (NWF-WRC) | D7: 98 | E7: 0.39 | F7: 0.25 | G7: 0.26 | H7: 0.1 | I7: 0.36 | J7: 0.21 | K7: 0.3 | L7: 0.13 | M7: 0.15 | N7: 0.15 | O7: 0.43 | P7: 0.27 | Q7: =SUM(G7:H7) -> 0.36 | R7: =SUM(K7:L7) -> 0.43 | S7: =SUM(O7:P7) -> 0.7 | T7: =S7-Q7 -> 0.34
A8: 2023 | B8: 1 | C8: Decoding (NWF-WRC) | D8: 100 | E8: 0.34 | F8: 0.27 | G8: 0.23 | H8: 0.16 | I8: 0.21 | J8: 0.19 | K8: 0.42 | L8: 0.18 | M8: 0.1 | N8: 0.1 | O8: 0.41 | P8: 0.39 | Q8: =SUM(G8:H8) -> 0.39 | R8: =SUM(K8:L8) -> 0.6 | S8: =SUM(O8:P8) -> 0.8 | T8: =S8-Q8 -> 0.41
A9: 2024 | B9: 1 | C9: Decoding (NWF-WRC) | D9: 106 | E9: 0.18 | F9: 0.18 | G9: 0.45 | H9: 0.19 | I9: 0.22 | J9: 0.13 | K9: 0.38 | L9: 0.27 | M9: 0.12 | N9: 0.05 | O9: 0.45 | P9: 0.38 | Q9: =SUM(G9:H9) -> 0.64 | R9: =SUM(K9:L9) -> 0.65 | S9: =SUM(O9:P9) -> 0.83 | T9: =S9-Q9 -> 0.19
A10: 2025 | B10: 1 | C10: Decoding (NWF-WRC) | D10: 95 | E10: 0.07 | F10: 0.26 | G10: 0.39 | H10: 0.28 | I10: 0.14 | J10: 0.19 | K10: 0.38 | L10: 0.29 | M10: 0.12 | N10: 0.14 | O10: 0.37 | P10: 0.37 | Q10: =SUM(G10:H10) -> 0.67 | R10: =SUM(K10:L10) -> 0.67 | S10: =SUM(O10:P10) -> 0.74 | T10: =S10-Q10 -> 0.07
A11: 2026 | B11: 1 | C11: Decoding (NWF-WRC) | D11: 88 | E11: 0.06 | F11: 0.11 | G11: 0.55 | H11: 0.28 | I11: 0.08 | J11: 0.2 | K11: 0.48 | L11: 0.24 | M11: 0.06 | N11: 0.01 | O11: 0.5 | P11: 0.43 | Q11: =SUM(G11:H11) -> 0.83 | R11: =SUM(K11:L11) -> 0.72 | S11: =SUM(O11:P11) -> 0.93 | T11: =S11-Q11 -> 0.1
A12: 2022 | B12: 1 | C12: Letter Names (LNF) | D12: 98 | E12: 0.33 | F12: 0.27 | G12: 0.4 | I12: 0.35 | J12: 0.11 | K12: 0.54 | M12: 0.12 | N12: 0.06 | O12: 0.82 | Q12: =SUM(G12:H12) -> 0.4 | R12: =SUM(K12:L12) -> 0.54 | S12: =SUM(O12:P12) -> 0.82 | T12: =S12-Q12 -> 0.42
A13: 2023 | B13: 1 | C13: Letter Names (LNF) | D13: 100 | E13: 0.3 | F13: 0.24 | G13: 0.46 | I13: 0.19 | J13: 0.09 | K13: 0.72 | M13: 0.06 | O13: 0.93 | Q13: =SUM(G13:H13) -> 0.46 | R13: =SUM(K13:L13) -> 0.72 | S13: =SUM(O13:P13) -> 0.93 | T13: =S13-Q13 -> 0.47
A14: 2024 | B14: 1 | C14: Letter Names (LNF) | D14: 106 | E14: 0.15 | F14: 0.17 | G14: 0.68 | I14: 0.13 | J14: 0.07 | K14: 0.8 | M14: 0.03 | N14: 0.04 | O14: 0.93 | Q14: =SUM(G14:H14) -> 0.68 | R14: =SUM(K14:L14) -> 0.8 | S14: =SUM(O14:P14) -> 0.93 | T14: =S14-Q14 -> 0.25
A15: 2025 | B15: 1 | C15: Letter Names (LNF) | D15: 95 | E15: 0.2 | F15: 0.22 | G15: 0.58 | I15: 0.18 | J15: 0.09 | K15: 0.73 | M15: 0.11 | N15: 0.14 | O15: 0.75 | Q15: =SUM(G15:H15) -> 0.58 | R15: =SUM(K15:L15) -> 0.73 | S15: =SUM(O15:P15) -> 0.75 | T15: =S15-Q15 -> 0.17
A16: 2026 | B16: 1 | C16: Letter Names (LNF) | D16: 88 | E16: 0.17 | F16: 0.2 | G16: 0.63 | I16: 0.23 | J16: 0.07 | K16: 0.7 | M16: 0.07 | N16: 0.09 | O16: 0.84 | Q16: =SUM(G16:H16) -> 0.63 | R16: =SUM(K16:L16) -> 0.7 | S16: =SUM(O16:P16) -> 0.84 | T16: =S16-Q16 -> 0.21
A17: 2022 | B17: 1 | C17: Letter Sounds (NWF-CLS) | D17: 98 | E17: 0.39 | F17: 0.17 | G17: 0.25 | H17: 0.19 | I17: 0.5 | J17: 0.14 | K17: 0.23 | L17: 0.13 | M17: 0.18 | N17: 0.18 | O17: 0.37 | P17: 0.27 | Q17: =SUM(G17:H17) -> 0.44 | R17: =SUM(K17:L17) -> 0.36 | S17: =SUM(O17:P17) -> 0.64 | T17: =S17-Q17 -> 0.2
A18: 2023 | B18: 1 | C18: Letter Sounds (NWF-CLS) | D18: 100 | E18: 0.43 | F18: 0.11 | G18: 0.25 | H18: 0.21 | I18: 0.25 | J18: 0.23 | K18: 0.34 | L18: 0.18 | M18: 0.1 | N18: 0.1 | O18: 0.4 | P18: 0.4 | Q18: =SUM(G18:H18) -> 0.46 | R18: =SUM(K18:L18) -> 0.52 | S18: =SUM(O18:P18) -> 0.8 | T18: =S18-Q18 -> 0.34
A19: 2024 | B19: 1 | C19: Letter Sounds (NWF-CLS) | D19: 106 | E19: 0.24 | F19: 0.13 | G19: 0.32 | H19: 0.31 | I19: 0.2 | J19: 0.18 | K19: 0.33 | L19: 0.29 | M19: 0.09 | N19: 0.12 | O19: 0.36 | P19: 0.43 | Q19: =SUM(G19:H19) -> 0.63 | R19: =SUM(K19:L19) -> 0.62 | S19: =SUM(O19:P19) -> 0.79 | T19: =S19-Q19 -> 0.16
A20: 2025 | B20: 1 | C20: Letter Sounds (NWF-CLS) | D20: 95 | E20: 0.27 | F20: 0.15 | G20: 0.26 | H20: 0.32 | I20: 0.19 | J20: 0.27 | K20: 0.19 | L20: 0.35 | M20: 0.15 | N20: 0.16 | O20: 0.34 | P20: 0.35 | Q20: =SUM(G20:H20) -> 0.58 | R20: =SUM(K20:L20) -> 0.54 | S20: =SUM(O20:P20) -> 0.69 | T20: =S20-Q20 -> 0.11
A21: 2026 | B21: 1 | C21: Letter Sounds (NWF-CLS) | D21: 88 | E21: 0.11 | F21: 0.09 | G21: 0.43 | H21: 0.37 | I21: 0.15 | J21: 0.17 | K21: 0.4 | L21: 0.28 | M21: 0.04 | N21: 0.06 | O21: 0.45 | P21: 0.44 | Q21: =SUM(G21:H21) -> 0.8 | R21: =SUM(K21:L21) -> 0.68 | S21: =SUM(O21:P21) -> 0.89 | T21: =S21-Q21 -> 0.09
A22: 2022 | B22: 1 | C22: Phonemic Awareness (PSF) | D22: 98 | E22: 0.19 | F22: 0.26 | G22: 0.39 | H22: 0.16 | I22: 0.27 | J22: 0.27 | K22: 0.33 | L22: 0.13 | M22: 0.08 | N22: 0.14 | O22: 0.55 | P22: 0.23 | Q22: =SUM(G22:H22) -> 0.55 | R22: =SUM(K22:L22) -> 0.46 | S22: =SUM(O22:P22) -> 0.78 | T22: =S22-Q22 -> 0.23
A23: 2023 | B23: 1 | C23: Phonemic Awareness (PSF) | D23: 100 | E23: 0.15 | F23: 0.19 | G23: 0.5 | H23: 0.16 | I23: 0.07 | K23: 0.48 | L23: 0.42 | M23: 0.06 | O23: 0.34 | P23: 0.58 | Q23: =SUM(G23:H23) -> 0.66 | R23: =SUM(K23:L23) -> 0.9 | S23: =SUM(O23:P23) -> 0.92 | T23: =S23-Q23 -> 0.26
A24: 2024 | B24: 1 | C24: Phonemic Awareness (PSF) | D24: 106 | E24: 0.1 | F24: 0.14 | G24: 0.44 | H24: 0.32 | I24: 0.05 | J24: 0.05 | K24: 0.31 | L24: 0.59 | M24: 0.03 | N24: 0.02 | O24: 0.25 | P24: 0.7 | Q24: =SUM(G24:H24) -> 0.76 | R24: =SUM(K24:L24) -> 0.9 | S24: =SUM(O24:P24) -> 0.95 | T24: =S24-Q24 -> 0.19
A25: 2025 | B25: 1 | C25: Phonemic Awareness (PSF) | D25: 95 | E25: 0.05 | F25: 0.22 | G25: 0.5 | H25: 0.23 | J25: 0.09 | K25: 0.4 | L25: 0.46 | M25: 0.01 | N25: 0.04 | O25: 0.4 | P25: 0.55 | Q25: =SUM(G25:H25) -> 0.73 | R25: =SUM(K25:L25) -> 0.86 | S25: =SUM(O25:P25) -> 0.95 | T25: =S25-Q25 -> 0.22
A26: 2026 | B26: 1 | C26: Phonemic Awareness (PSF) | D26: 88 | E26: 0.07 | F26: 0.11 | G26: 0.32 | H26: 0.5 | J26: 0.1 | K26: 0.26 | L26: 0.61 | M26: 0.01 | N26: 0.01 | O26: 0.26 | P26: 0.72 | Q26: =SUM(G26:H26) -> 0.82 | R26: =SUM(K26:L26) -> 0.87 | S26: =SUM(O26:P26) -> 0.98 | T26: =S26-Q26 -> 0.16
A27: 2022 | B27: 1 | C27: Reading Accuracy (ORF-Accu) | D27: 98 | E27: 0.42 | F27: 0.17 | G27: 0.39 | I27: 0.25 | J27: 0.37 | K27: 0.38 | M27: 0.23 | N27: 0.13 | O27: 0.64 | Q27: =SUM(G27:H27) -> 0.39 | R27: =SUM(K27:L27) -> 0.38 | S27: =SUM(O27:P27) -> 0.64 | T27: =S27-Q27 -> 0.25
A28: 2023 | B28: 1 | C28: Reading Accuracy (ORF-Accu) | D28: 100 | E28: 0.46 | F28: 0.19 | G28: 0.33 | I28: 0.34 | J28: 0.27 | K28: 0.39 | M28: 0.24 | N28: 0.11 | O28: 0.65 | Q28: =SUM(G28:H28) -> 0.33 | R28: =SUM(K28:L28) -> 0.39 | S28: =SUM(O28:P28) -> 0.65 | T28: =S28-Q28 -> 0.32
A29: 2024 | B29: 1 | C29: Reading Accuracy (ORF-Accu) | D29: 106 | E29: 0.26 | F29: 0.25 | G29: 0.49 | I29: 0.17 | J29: 0.34 | K29: 0.49 | M29: 0.17 | N29: 0.06 | O29: 0.77 | Q29: =SUM(G29:H29) -> 0.49 | R29: =SUM(K29:L29) -> 0.49 | S29: =SUM(O29:P29) -> 0.77 | T29: =S29-Q29 -> 0.28
A30: 2025 | B30: 1 | C30: Reading Accuracy (ORF-Accu) | D30: 95 | E30: 0.35 | F30: 0.22 | G30: 0.43 | I30: 0.21 | J30: 0.33 | K30: 0.46 | M30: 0.19 | N30: 0.14 | O30: 0.67 | Q30: =SUM(G30:H30) -> 0.43 | R30: =SUM(K30:L30) -> 0.46 | S30: =SUM(O30:P30) -> 0.67 | T30: =S30-Q30 -> 0.24
A31: 2026 | B31: 1 | C31: Reading Accuracy (ORF-Accu) | D31: 88 | E31: 0.27 | F31: 0.17 | G31: 0.56 | I31: 0.16 | J31: 0.3 | K31: 0.54 | M31: 0.13 | N31: 0.18 | O31: 0.69 | Q31: =SUM(G31:H31) -> 0.56 | R31: =SUM(K31:L31) -> 0.54 | S31: =SUM(O31:P31) -> 0.69 | T31: =S31-Q31 -> 0.13
A32: 2022 | B32: 1 | C32: Reading Fluency (ORF) | D32: 98 | E32: 0.35 | F32: 0.18 | G32: 0.26 | H32: 0.19 | I32: 0.33 | J32: 0.19 | K32: 0.28 | L32: 0.2 | M32: 0.13 | N32: 0.29 | O32: 0.24 | P32: 0.34 | Q32: =SUM(G32:H32) -> 0.45 | R32: =SUM(K32:L32) -> 0.48 | S32: =SUM(O32:P32) -> 0.58 | T32: =S32-Q32 -> 0.13
A33: 2023 | B33: 1 | C33: Reading Fluency (ORF) | D33: 100 | E33: 0.37 | F33: 0.15 | G33: 0.31 | H33: 0.15 | I33: 0.38 | J33: 0.15 | K33: 0.25 | L33: 0.22 | M33: 0.16 | N33: 0.19 | O33: 0.3 | P33: 0.35 | Q33: =SUM(G33:H33) -> 0.46 | R33: =SUM(K33:L33) -> 0.47 | S33: =SUM(O33:P33) -> 0.65 | T33: =S33-Q33 -> 0.19
A34: 2024 | B34: 1 | C34: Reading Fluency (ORF) | D34: 106 | E34: 0.25 | F34: 0.1 | G34: 0.39 | H34: 0.26 | I34: 0.19 | J34: 0.12 | K34: 0.39 | L34: 0.3 | M34: 0.16 | N34: 0.09 | O34: 0.29 | P34: 0.46 | Q34: =SUM(G34:H34) -> 0.65 | R34: =SUM(K34:L34) -> 0.69 | S34: =SUM(O34:P34) -> 0.75 | T34: =S34-Q34 -> 0.1
A35: 2025 | B35: 1 | C35: Reading Fluency (ORF) | D35: 95 | E35: 0.3 | F35: 0.13 | G35: 0.33 | H35: 0.24 | I35: 0.24 | J35: 0.16 | K35: 0.25 | L35: 0.35 | M35: 0.21 | N35: 0.13 | O35: 0.22 | P35: 0.44 | Q35: =SUM(G35:H35) -> 0.57 | R35: =SUM(K35:L35) -> 0.6 | S35: =SUM(O35:P35) -> 0.66 | T35: =S35-Q35 -> 0.09
A36: 2026 | B36: 1 | C36: Reading Fluency (ORF) | D36: 88 | E36: 0.22 | F36: 0.18 | G36: 0.33 | H36: 0.27 | I36: 0.22 | J36: 0.1 | K36: 0.31 | L36: 0.37 | M36: 0.1 | N36: 0.18 | O36: 0.25 | P36: 0.47 | Q36: =SUM(G36:H36) -> 0.6 | R36: =SUM(K36:L36) -> 0.68 | S36: =SUM(O36:P36) -> 0.72 | T36: =S36-Q36 -> 0.12
A37: 2023 | B37: 1 | C37: Word Reading (WRF) | D37: 100 | E37: 0.37 | F37: 0.17 | G37: 0.24 | H37: 0.22 | I37: 0.26 | J37: 0.17 | K37: 0.31 | L37: 0.26 | M37: 0.17 | N37: 0.22 | O37: 0.28 | P37: 0.33 | Q37: =SUM(G37:H37) -> 0.46 | R37: =SUM(K37:L37) -> 0.57 | S37: =SUM(O37:P37) -> 0.61 | T37: =S37-Q37 -> 0.15
A38: 2025 | B38: 1 | C38: Word Reading (WRF) | D38: 95 | E38: 0.29 | F38: 0.2 | G38: 0.21 | H38: 0.3 | I38: 0.19 | J38: 0.12 | K38: 0.33 | L38: 0.36 | M38: 0.15 | N38: 0.21 | O38: 0.24 | P38: 0.4 | Q38: =SUM(G38:H38) -> 0.51 | R38: =SUM(K38:L38) -> 0.69 | S38: =SUM(O38:P38) -> 0.64 | T38: =S38-Q38 -> 0.13
A39: 2026 | B39: 1 | C39: Word Reading (WRF) | D39: 88 | E39: 0.24 | F39: 0.11 | G39: 0.35 | H39: 0.3 | I39: 0.13 | J39: 0.17 | K39: 0.28 | L39: 0.42 | M39: 0.09 | N39: 0.21 | O39: 0.27 | P39: 0.43 | Q39: =SUM(G39:H39) -> 0.65 | R39: =SUM(K39:L39) -> 0.7 | S39: =SUM(O39:P39) -> 0.7 | T39: =S39-Q39 -> 0.05
A40: 2022 | B40: 1 | C40: Word Reading (WRF) | D40: 98 | E40: 0.38 | F40: 0.17 | G40: 0.23 | H40: 0.22 | I40: 0.31 | J40: 0.13 | K40: 0.31 | L40: 0.25 | M40: 0.16 | N40: 0.27 | O40: 0.27 | P40: 0.3 | Q40: =SUM(G40:H40) -> 0.45 | R40: =SUM(K40:L40) -> 0.56 | S40: =SUM(O40:P40) -> 0.57 | T40: =S40-Q40 -> 0.12
...
